2022-06-26 00:56:27,864 - INFO - Started server process [4408]
2022-06-26 00:56:27,865 - INFO - Waiting for application startup.
2022-06-26 00:56:27,866 - INFO - Application startup complete.
2022-06-26 00:56:40,789 - INFO - POST Request: Coordinates
2022-06-26 00:56:41,720 - ERROR - Exception in ASGI application
Traceback (most recent call last):
  File "C:\Users\sastry\AppData\Roaming\Python\Python38\site-packages\uvicorn\protocols\http\h11_impl.py", line 366, in run_asgi
    result = await app(self.scope, self.receive, self.send)
  File "C:\Users\sastry\AppData\Roaming\Python\Python38\site-packages\uvicorn\middleware\proxy_headers.py", line 75, in __call__
    return await self.app(scope, receive, send)
  File "C:\Users\sastry\AppData\Roaming\Python\Python38\site-packages\fastapi\applications.py", line 269, in __call__
    await super().__call__(scope, receive, send)
  File "C:\Users\sastry\AppData\Roaming\Python\Python38\site-packages\starlette\applications.py", line 124, in __call__
    await self.middleware_stack(scope, receive, send)
  File "C:\Users\sastry\AppData\Roaming\Python\Python38\site-packages\starlette\middleware\errors.py", line 184, in __call__
    raise exc
  File "C:\Users\sastry\AppData\Roaming\Python\Python38\site-packages\starlette\middleware\errors.py", line 162, in __call__
    await self.app(scope, receive, _send)
  File "C:\Users\sastry\AppData\Roaming\Python\Python38\site-packages\starlette\exceptions.py", line 93, in __call__
    raise exc
  File "C:\Users\sastry\AppData\Roaming\Python\Python38\site-packages\starlette\exceptions.py", line 82, in __call__
    await self.app(scope, receive, sender)
  File "C:\Users\sastry\AppData\Roaming\Python\Python38\site-packages\fastapi\middleware\asyncexitstack.py", line 21, in __call__
    raise e
  File "C:\Users\sastry\AppData\Roaming\Python\Python38\site-packages\fastapi\middleware\asyncexitstack.py", line 18, in __call__
    await self.app(scope, receive, send)
  File "C:\Users\sastry\AppData\Roaming\Python\Python38\site-packages\starlette\routing.py", line 670, in __call__
    await route.handle(scope, receive, send)
  File "C:\Users\sastry\AppData\Roaming\Python\Python38\site-packages\starlette\routing.py", line 266, in handle
    await self.app(scope, receive, send)
  File "C:\Users\sastry\AppData\Roaming\Python\Python38\site-packages\starlette\routing.py", line 65, in app
    response = await func(request)
  File "C:\Users\sastry\AppData\Roaming\Python\Python38\site-packages\fastapi\routing.py", line 227, in app
    raw_response = await run_endpoint_function(
  File "C:\Users\sastry\AppData\Roaming\Python\Python38\site-packages\fastapi\routing.py", line 162, in run_endpoint_function
    return await run_in_threadpool(dependant.call, **values)
  File "C:\Users\sastry\AppData\Roaming\Python\Python38\site-packages\starlette\concurrency.py", line 41, in run_in_threadpool
    return await anyio.to_thread.run_sync(func, *args)
  File "C:\Users\sastry\AppData\Roaming\Python\Python38\site-packages\anyio\to_thread.py", line 31, in run_sync
    return await get_asynclib().run_sync_in_worker_thread(
  File "C:\Users\sastry\AppData\Roaming\Python\Python38\site-packages\anyio\_backends\_asyncio.py", line 937, in run_sync_in_worker_thread
    return await future
  File "C:\Users\sastry\AppData\Roaming\Python\Python38\site-packages\anyio\_backends\_asyncio.py", line 867, in run
    result = context.run(func, *args)
  File ".\main.py", line 111, in create_coordinates
    location_data = Coordinates(address)  # calling coodinates function which will get the coordinates from given api
  File ".\coordinate\coordinate.py", line 9, in Coordinates
    a=[response_location[0]["lat"] , response_location[0]["lon"]]
IndexError: list index out of range
2022-06-26 00:57:19,526 - INFO - POST Request: Coordinates
2022-06-26 00:57:20,491 - INFO - POST Request: Success
